Workbook

Sheet 肉类、海鲜（涮菜）
A1: 菜品成本卡
A2: 菜品 | B2: 名称 | C2: 分类 | D2: 进货渠道 | E2: 品牌 | F2: 采购价格(元) | G2: 基础单位数量(g) | H2: 标准出成率 | I2: 基础单价(元/g) | J2: 配方用量(g) | K2: 理论成本(元) | L2: 备注
A3: 云山雪花吊龙 | B3: 吊龙 | C3: =VLOOKUP(B3,原材料价格表!$B$2:$J$242,9,) | D3: =VLOOKUP(B3,原材料价格表!$B$2:$G$436,2,0) | E3: =VLOOKUP(B3,原材料价格表!$B$2:$G$436,4,0) | F3: =VLOOKUP(B3,原材料价格表!$B$2:$G$436,6,0) | G3: =VLOOKUP(B3,原材料价格表!$B$2:$G$436,5,0) | H3: 0.9 | I3: =F3/G3/H3 | J3: 250 | K3: =I3*J3
B4: 法香 | C4: =VLOOKUP(B4,原材料价格表!$B$2:$J$242,9,) | D4: =VLOOKUP(B4,原材料价格表!$B$2:$G$436,2,0) | E4: =VLOOKUP(B4,原材料价格表!$B$2:$G$436,4,0) | F4: =VLOOKUP(B4,原材料价格表!$B$2:$G$436,6,0) | G4: =VLOOKUP(B4,原材料价格表!$B$2:$G$436,5,0) | H4: 1 | I4: =F4/G4/H4 | J4: 120 | K4: =I4*J4
B5: 干冰 | C5: =VLOOKUP(B5,原材料价格表!$B$2:$J$242,9,) | D5: =VLOOKUP(B5,原材料价格表!$B$2:$G$436,2,0) | E5: =VLOOKUP(B5,原材料价格表!$B$2:$G$436,4,0) | F5: =VLOOKUP(B5,原材料价格表!$B$2:$G$436,6,0) | G5: =VLOOKUP(B5,原材料价格表!$B$2:$G$436,5,0) | H5: 1 | I5: =F5/G5/H5 | J5: 20 | K5: =I5*J5
B6: 售价 | D6: 88 | E6: 售卖份量/g | F6: =SUM(J3:J5) | G6: 总成本（元） | H6: =SUM(K3:K5) | I6: 毛利/元 | J6: =D6-H6 | K6: 毛利率 | L6: =J6/D6
A7: 木姜子鲜黄牛肉 | B7: 吊龙 | C7: =VLOOKUP(B7,原材料价格表!$B$2:$J$242,9,) | D7: =VLOOKUP(B7,原材料价格表!$B$2:$G$436,2,0) | E7: =VLOOKUP(B7,原材料价格表!$B$2:$G$436,3,0) | F7: =VLOOKUP(B7,原材料价格表!$B$2:$G$436,6,0) | G7: =VLOOKUP(B7,原材料价格表!$B$2:$G$436,5,0) | H7: 0.9 | I7: =F7/G7/H7 | J7: 120 | K7: =I7*J7
B8: 木姜子 | C8: =VLOOKUP(B8,原材料价格表!$B$2:$J$242,9,) | D8: =VLOOKUP(B8,原材料价格表!$B$2:$G$436,2,0) | E8: =VLOOKUP(B8,原材料价格表!$B$2:$G$436,3,0) | F8: =VLOOKUP(B8,原材料价格表!$B$2:$G$436,6,0) | G8: =VLOOKUP(B8,原材料价格表!$B$2:$G$436,5,0) | H8: 1 | I8: =F8/G8/H8 | J8: 60 | K8: =I8*J8
B9: 售价 | D9: 42 | E9: 售卖份量/g | F9: =SUM(J7:J8) | G9: 总成本（元） | H9: =SUM(K7:K8) | I9: 毛利/元 | J9: =D9-H9 | K9: 毛利率 | L9: =J9/D9
A10: 糊辣椒鲜黄牛匙仁 | B10: 匙仁 | C10: =VLOOKUP(B10,原材料价格表!$B$2:$J$242,9,) | D10: =VLOOKUP(B10,原材料价格表!$B$2:$G$436,2,0) | E10: =VLOOKUP(B10,原材料价格表!$B$2:$G$436,3,0) | F10: =VLOOKUP(B10,原材料价格表!$B$2:$G$436,6,0) | G10: =VLOOKUP(B10,原材料价格表!$B$2:$G$436,5,0) | H10: 0.9 | I10: =F10/G10/H10 | J10: 120 | K10: =I10*J10
B11: 糊辣椒 | C11: =VLOOKUP(B11,原材料价格表!$B$2:$J$242,9,) | D11: =VLOOKUP(B11,原材料价格表!$B$2:$G$436,2,0) | E11: =VLOOKUP(B11,原材料价格表!$B$2:$G$436,3,0) | F11: 25 | G11: =VLOOKUP(B11,原材料价格表!$B$2:$G$436,5,0) | H11: 1 | I11: =F11/G11/H11 | J11: 25 | K11: =I11*J11
B12: 干香茅草 | C12: =VLOOKUP(B12,原材料价格表!$B$2:$J$242,9,) | D12: =VLOOKUP(B12,原材料价格表!$B$2:$G$436,2,0) | E12: =VLOOKUP(B12,原材料价格表!$B$2:$G$436,3,0) | F12: =VLOOKUP(B12,原材料价格表!$B$2:$G$436,6,0) | G12: =VLOOKUP(B12,原材料价格表!$B$2:$G$436,5,0) | H12: 1 | I12: =F12/G12/H12 | J12: 25 | K12: =I12*J12
B13: 售价 | D13: 38 | E13: 售卖份量/g | F13: =SUM(J10:J12) | G13: 总成本（元） | H13: =SUM(K10:K12) | I13: 毛利/元 | J13: =D13-H13 | K13: 毛利率 | L13: =J13/D13
A14: 野蒜酥五花趾 | B14: 五花腱 | C14: =VLOOKUP(B14,原材料价格表!$B$2:$J$242,9,) | D14: =VLOOKUP(B14,原材料价格表!$B$2:$G$436,2,0) | E14: =VLOOKUP(B14,原材料价格表!$B$2:$G$436,3,0) | F14: =VLOOKUP(B14,原材料价格表!$B$2:$G$436,6,0) | G14: =VLOOKUP(B14,原材料价格表!$B$2:$G$436,5,0) | H14: 0.9 | I14: =F14/G14/H14 | J14: 120 | K14: =I14*J14
B15: 金蒜酥 | C15: =VLOOKUP(B15,原材料价格表!$B$2:$J$242,9,) | D15: =VLOOKUP(B15,原材料价格表!$B$2:$G$436,2,0) | E15: =VLOOKUP(B15,原材料价格表!$B$2:$G$436,3,0) | F15: =VLOOKUP(B15,原材料价格表!$B$2:$G$436,6,0) | G15: =VLOOKUP(B15,原材料价格表!$B$2:$G$436,5,0) | H15: 1 | I15: =F15/G15/H15 | J15: 40 | K15: =I15*J15
B16: 售价 | D16: 38 | E16: 售卖份量/g | F16: =SUM(J14:J15) | G16: 总成本（元） | H16: =SUM(K14:K15) | I16: 毛利/元 | J16: =D16-H16 | K16: 毛利率 | L16: =J16/D16
A17: 紫苏半边云 | B17: 胸口油 | C17: =VLOOKUP(B17,原材料价格表!$B$2:$J$242,9,) | D17: =VLOOKUP(B17,原材料价格表!$B$2:$G$436,2,0) | E17: =VLOOKUP(B17,原材料价格表!$B$2:$G$436,3,0) | F17: =VLOOKUP(B17,原材料价格表!$B$2:$G$436,6,0) | G17: =VLOOKUP(B17,原材料价格表!$B$2:$G$436,5,0) | H17: 0.7 | I17: =F17/G17/H17 | J17: 120 | K17: =I17*J17
B18: 紫苏叶 | C18: =VLOOKUP(B18,原材料价格表!$B$2:$J$242,9,) | D18: =VLOOKUP(B18,原材料价格表!$B$2:$G$436,2,0) | E18: =VLOOKUP(B18,原材料价格表!$B$2:$G$436,3,0) | F18: =VLOOKUP(B18,原材料价格表!$B$2:$G$436,6,0) | G18: =VLOOKUP(B18,原材料价格表!$B$2:$G$436,5,0) | H18: 1 | I18: =F18/G18/H18 | J18: 10 | K18: =I18*J18
B19: 紫苏碎 | C19: =VLOOKUP(B19,原材料价格表!$B$2:$J$242,9,) | D19: =VLOOKUP(B19,原材料价格表!$B$2:$G$436,2,0) | E19: =VLOOKUP(B19,原材料价格表!$B$2:$G$436,3,0) | F19: =VLOOKUP(B19,原材料价格表!$B$2:$G$436,6,0) | G19: =VLOOKUP(B19,原材料价格表!$B$2:$G$436,5,0) | H19: 1 | I19: =F19/G19/H19 | J19: 5 | K19: =I19*J19
B20: 售价 | D20: 38 | E20: 售卖份量/g | F20: =SUM(J17:J19) | G20: 总成本（元） | H20: =SUM(K17:K19) | I20: 毛利/元 | J20: =D20-H20 | K20: 毛利率 | L20: =J20/D20
A21: 大地飞雪(M9纯血和牛) | B21: M9和牛 | C21: =VLOOKUP(B21,原材料价格表!$B$2:$J$242,9,) | D21: =VLOOKUP(B21,原材料价格表!$B$2:$G$436,2,0) | E21: =VLOOKUP(B21,原材料价格表!$B$2:$G$436,3,0) | F21: =VLOOKUP(B21,原材料价格表!$B$2:$G$436,6,0) | G21: =VLOOKUP(B21,原材料价格表!$B$2:$G$436,5,0) | H21: 0.85 | I21: =F21/G21/H21 | J21: 200 | K21: =I21*J21
B22: 售价 | D22: 128 | E22: 售卖份量/g | F22: =SUM(J21) | G22: 总成本（元） | H22: =SUM(K21) | I22: 毛利/元 | J22: =D22-H22 | K22: 毛利率 | L22: =J22/D22
A23: 黑松露和牛肉开口笑 | B23: 和牛肉糜 | C23: =VLOOKUP(B23,原材料价格表!$B$2:$J$242,9,) | D23: =VLOOKUP(B23,原材料价格表!$B$2:$G$436,2,0) | E23: =VLOOKUP(B23,原材料价格表!$B$2:$G$436,3,0) | F23: =VLOOKUP(B23,原材料价格表!$B$2:$G$436,6,0) | G23: =VLOOKUP(B23,原材料价格表!$B$2:$G$436,5,0) | H23: 1 | I23: =F23/G23/H23 | J23: 110 | K23: =I23*J23
B24: 黑松露酱 | C24: =VLOOKUP(B24,原材料价格表!$B$2:$J$242,9,) | D24: =VLOOKUP(B24,原材料价格表!$B$2:$G$436,2,0) | E24: =VLOOKUP(B24,原材料价格表!$B$2:$G$436,3,0) | F24: =VLOOKUP(B24,原材料价格表!$B$2:$G$436,6,0) | G24: =VLOOKUP(B24,原材料价格表!$B$2:$G$436,5,0) | H24: 1 | I24: =F24/G24/H24 | J24: 5 | K24: =I24*J24 | N24: =61/2
B25: 饺子皮 | C25: =VLOOKUP(B25,原材料价格表!$B$2:$J$242,9,) | D25: =VLOOKUP(B25,原材料价格表!$B$2:$G$436,2,0) | E25: =VLOOKUP(B25,原材料价格表!$B$2:$G$436,3,0) | F25: =VLOOKUP(B25,原材料价格表!$B$2:$G$436,6,0) | G25: =VLOOKUP(B25,原材料价格表!$B$2:$G$436,5,0) | H25: 1 | I25: =F25/G25/H25 | J25: 60 | K25: =I25*J25
B26: 售价 | D26: 28 | E26: 售卖份量/g | F26: =SUM(J23:J25) | G26: 总成本（元） | H26: =SUM(K23:K25) | I26: 毛利/元 | J26: =D26-H26 | K26: 毛利率 | L26: =J26/D26
A27: 黑松露和牛肉开口笑 | B27: 匙仁 | C27: =VLOOKUP(B27,原材料价格表!$B$2:$J$242,9,) | D27: =VLOOKUP(B27,原材料价格表!$B$2:$G$436,2,0) | E27: =VLOOKUP(B27,原材料价格表!$B$2:$G$436,3,0) | F27: =VLOOKUP(B27,原材料价格表!$B$2:$G$436,6,0) | G27: =VLOOKUP(B27,原材料价格表!$B$2:$G$436,5,0) | H27: 0.9 | I27: =F27/G27/H27 | J27: =110/4 | K27: =I27*J27
B28: 胸口油 | C28: =VLOOKUP(B28,原材料价格表!$B$2:$J$242,9,) | D28: =VLOOKUP(B28,原材料价格表!$B$2:$G$436,2,0) | E28: =VLOOKUP(B28,原材料价格表!$B$2:$G$436,3,0) | F28: =VLOOKUP(B28,原材料价格表!$B$2:$G$436,6,0) | G28: =VLOOKUP(B28,原材料价格表!$B$2:$G$436,5,0) | H28: 0.9 | I28: =F28/G28/H28 | J28: =110/4 | K28: =I28*J28
B29: 五花腱 | C29: =VLOOKUP(B29,原材料价格表!$B$2:$J$242,9,) | D29: =VLOOKUP(B29,原材料价格表!$B$2:$G$436,2,0) | E29: =VLOOKUP(B29,原材料价格表!$B$2:$G$436,3,0) | F29: =VLOOKUP(B29,原材料价格表!$B$2:$G$436,6,0) | G29: =VLOOKUP(B29,原材料价格表!$B$2:$G$436,5,0) | H29: 0.9 | I29: =F29/G29/H29 | J29: =110/4 | K29: =I29*J29
B30: M9和牛 | C30: =VLOOKUP(B30,原材料价格表!$B$2:$J$242,9,) | D30: =VLOOKUP(B30,原材料价格表!$B$2:$G$436,2,0) | E30: =VLOOKUP(B30,原材料价格表!$B$2:$G$436,3,0) | F30: =VLOOKUP(B30,原材料价格表!$B$2:$G$436,6,0) | G30: =VLOOKUP(B30,原材料价格表!$B$2:$G$436,5,0) | H30: 0.9 | I30: =F30/G30/H30 | J30: =110/4 | K30: =I30*J30
B31: 黑松露酱 | C31: =VLOOKUP(B31,原材料价格表!$B$2:$J$242,9,) | D31: =VLOOKUP(B31,原材料价格表!$B$2:$G$436,2,0) | E31: =VLOOKUP(B31,原材料价格表!$B$2:$G$436,3,0) | F31: =VLOOKUP(B31,原材料价格表!$B$2:$G$436,6,0) | G31: =VLOOKUP(B31,原材料价格表!$B$2:$G$436,5,0) | H31: 1 | I31: =F31/G31/H31 | J31: 5 | K31: =I31*J31
B32: 饺子皮 | C32: =VLOOKUP(B32,原材料价格表!$B$2:$J$242,9,) | D32: =VLOOKUP(B32,原材料价格表!$B$2:$G$436,2,0) | E32: =VLOOKUP(B32,原材料价格表!$B$2:$G$436,3,0) | F32: =VLOOKUP(B32,原材料价格表!$B$2:$G$436,6,0) | G32: =VLOOKUP(B32,原材料价格表!$B$2:$G$436,5,0) | H32: 1 | I32: =F32/G32/H32 | J32: 60 | K32: =I32*J32
B33: 售价 | D33: 28 | E33: 售卖份量/g | F33: =SUM(J27:J32) | G33: 总成本（元） | H33: =SUM(K27:K32) | I33: 毛利/元 | J33: =D33-H33 | K33: 毛利率 | L33: =J33/D33
A34: 贵州传统软哨 | B34: 软哨片 | C34: =VLOOKUP(B34,原材料价格表!$B$2:$J$242,9,) | D34: =VLOOKUP(B34,原材料价格表!$B$2:$G$436,2,0) | E34: =VLOOKUP(B34,原材料价格表!$B$2:$G$436,3,0) | F34: 36 | G34: =VLOOKUP(B34,原材料价格表!$B$2:$G$436,5,0) | H34: 1 | I34: =F34/G34/H34 | J34: 100 | K34: =I34*J34
B35: 芭蕉叶 | C35: =VLOOKUP(B35,原材料价格表!$B$2:$J$242,9,) | D35: =VLOOKUP(B35,原材料价格表!$B$2:$G$436,2,0) | E35: =VLOOKUP(B35,原材料价格表!$B$2:$G$436,3,0) | F35: =VLOOKUP(B35,原材料价格表!$B$2:$G$436,6,0) | G35: =VLOOKUP(B35,原材料价格表!$B$2:$G$436,5,0) | H35: 0.9 | I35: =F35/G35/H35 | J35: 5 | K35: =I35*J35
B36: 售价 | D36: 22 | E36: 售卖份量/g | F36: =SUM(J34:J35) | G36: 总成本（元） | H36: =SUM(K34:K35) | I36: 毛利/元 | J36: =D36-H36 | K36: 毛利率 | L36: =J36/D36
A37: 水晶滑肉混合物（半成品） | B37: 雪花松板肉 | C37: =VLOOKUP(B37,原材料价格表!$B$2:$J$242,9,) | D37: =VLOOKUP(B37,原材料价格表!$B$2:$G$436,2,0) | E37: =VLOOKUP(B37,原材料价格表!$B$2:$G$436,3,0) | F37: =VLOOKUP(B37,原材料价格表!$B$2:$G$436,6,0) | G37: =VLOOKUP(B37,原材料价格表!$B$2:$G$436,5,0) | H37: 1 | I37: =F37/G37/H37 | J37: 400 | K37: =I37*J37
B38: 红薯淀粉 | C38: =VLOOKUP(B38,原材料价格表!$B$2:$J$242,9,) | D38: =VLOOKUP(B38,原材料价格表!$B$2:$G$436,2,0) | E38: =VLOOKUP(B38,原材料价格表!$B$2:$G$436,3,0) | F38: =VLOOKUP(B38,原材料价格表!$B$2:$G$436,6,0) | G38: =VLOOKUP(B38,原材料价格表!$B$2:$G$436,5,0) | H38: 1 | I38: =F38/G38/H38 | J38: 150 | K38: =I38*J38
B39: 售价 | E39: 售卖份量/g | F39: 830 | G39: 总成本（元） | H39: =SUM(K37:K38) | I39: 毛利/元 | J39: =D39-H39 | K39: 毛利率 | L39: =J39/D39
A40: 手工水晶滑肉 | B40: 水晶滑肉混合物 | C40: =VLOOKUP(B40,原材料价格表!$B$2:$J$242,9,) | D40: =VLOOKUP(B40,原材料价格表!$B$2:$G$436,2,0) | E40: =VLOOKUP(B40,原材料价格表!$B$2:$G$436,3,0) | F40: =H39 | G40: =F39 | H40: 0.95 | I40: =F40/G40/H40 | J40: 200 | K40: =I40*J40
...

Sheet 糖水铺
A1: 菜品成本卡
A2: 菜品 | B2: 名称 | C2: 进货渠道 | D2: 品牌 | E2: 进价/元 | F2: 进货量/g | G2: 净货率 | H2: 单价/g | I2: 用量/g | J2: 成本/元 | K2: 备注
A3: 山茶花茶汤（半成品） | B3: 山茶花乌龙茶 | C3: =VLOOKUP(B3,原材料价格表!$B$2:$G$436,2,0) | D3: =VLOOKUP(B3,原材料价格表!$B$2:$G$436,4,0) | E3: =VLOOKUP(B3,原材料价格表!$B$2:$G$436,6,0) | F3: =VLOOKUP(B3,原材料价格表!$B$2:$G$436,5,0) | G3: 1 | H3: =E3/F3/G3 | I3: 30 | J3: =H3*I3
B4: 水 | C4: =VLOOKUP(B4,原材料价格表!$B$2:$G$436,2,0) | D4: =VLOOKUP(B4,原材料价格表!$B$2:$G$436,4,0) | E4: =VLOOKUP(B4,原材料价格表!$B$2:$G$436,6,0) | F4: =VLOOKUP(B4,原材料价格表!$B$2:$G$436,5,0) | G4: 1 | H4: =E4/F4/G4 | I4: 700 | J4: =H4*I4
B5: 冰块 | C5: =VLOOKUP(B5,原材料价格表!$B$2:$G$436,2,0) | D5: =VLOOKUP(B5,原材料价格表!$B$2:$G$436,4,0) | E5: =VLOOKUP(B5,原材料价格表!$B$2:$G$436,6,0) | F5: =VLOOKUP(B5,原材料价格表!$B$2:$G$436,5,0) | G5: 1 | H5: =E5/F5/G5 | I5: 50 | J5: =H5*I5
B6: 冰块 | C6: =VLOOKUP(B6,原材料价格表!$B$2:$G$436,2,0) | D6: =VLOOKUP(B6,原材料价格表!$B$2:$G$436,4,0) | E6: =VLOOKUP(B6,原材料价格表!$B$2:$G$436,6,0) | F6: =VLOOKUP(B6,原材料价格表!$B$2:$G$436,5,0) | G6: 1 | H6: =E6/F6/G6 | I6: 500 | J6: =H6*I6
B7: 售价 | D7: 售卖份量/g | E7: =SUM(I3:I6)-30 | F7: 总成本（元） | G7: =SUM(J3:J6) | H7: 毛利/元 | I7: =C7-G7 | J7: 毛利率 | K7: =I7/C7
A8: 野刺梨山茶 | B8: 刺梨原浆 | C8: =VLOOKUP(B8,原材料价格表!$B$2:$G$436,2,0) | D8: =VLOOKUP(B8,原材料价格表!$B$2:$G$436,4,0) | E8: =VLOOKUP(B8,原材料价格表!$B$2:$G$436,6,0) | F8: =VLOOKUP(B8,原材料价格表!$B$2:$G$436,5,0) | G8: 1 | H8: =E8/F8/G8 | I8: 100 | J8: =H8*I8
B9: 山茶花茶汤 | C9: =VLOOKUP(B9,原材料价格表!$B$2:$G$436,2,0) | D9: =VLOOKUP(B9,原材料价格表!$B$2:$G$436,4,0) | E9: =VLOOKUP(B9,原材料价格表!$B$2:$G$436,6,0) | F9: =VLOOKUP(B9,原材料价格表!$B$2:$G$436,5,0) | G9: 1 | H9: =E9/F9/G9 | I9: 150 | J9: =H9*I9
B10: 果葡糖浆 | C10: =VLOOKUP(B10,原材料价格表!$B$2:$G$436,2,0) | D10: =VLOOKUP(B10,原材料价格表!$B$2:$G$436,4,0) | E10: =VLOOKUP(B10,原材料价格表!$B$2:$G$436,6,0) | F10: =VLOOKUP(B10,原材料价格表!$B$2:$G$436,5,0) | G10: 1 | H10: =E10/F10/G10 | I10: 50 | J10: =H10*I10
B11: 冰块 | C11: =VLOOKUP(B11,原材料价格表!$B$2:$G$436,2,0) | D11: =VLOOKUP(B11,原材料价格表!$B$2:$G$436,4,0) | E11: =VLOOKUP(B11,原材料价格表!$B$2:$G$436,6,0) | F11: =VLOOKUP(B11,原材料价格表!$B$2:$G$436,5,0) | G11: 1 | H11: =E11/F11/G11 | I11: 200 | J11: =H11*I11
B12: 刺梨果干 | C12: =VLOOKUP(B12,原材料价格表!$B$2:$G$436,2,0) | D12: =VLOOKUP(B12,原材料价格表!$B$2:$G$436,4,0) | E12: =VLOOKUP(B12,原材料价格表!$B$2:$G$436,6,0) | F12: =VLOOKUP(B12,原材料价格表!$B$2:$G$436,5,0) | G12: 1 | H12: =E12/F12/G12 | I12: 30 | J12: =H12*I12
B13: 售价 | C13: 18 | D13: 售卖份量/g | E13: =SUM(I8:I12) | F13: 总成本（元） | G13: =SUM(J8:J12) | H13: 毛利/元 | I13: =C13-G13 | J13: 毛利率 | K13: =I13/C13
A14: 五指毛桃茶汤（半成品） | B14: 五指毛桃茶包 | C14: =VLOOKUP(B14,原材料价格表!$B$2:$G$436,2,0) | D14: =VLOOKUP(B14,原材料价格表!$B$2:$G$436,3,0) | E14: =VLOOKUP(B14,原材料价格表!$B$2:$G$436,6,0) | F14: =VLOOKUP(B14,原材料价格表!$B$2:$G$436,5,0) | G14: 1 | H14: =E14/F14/G14 | I14: 2 | J14: =H14*I14
B15: 水 | C15: =VLOOKUP(B15,原材料价格表!$B$2:$G$436,2,0) | D15: =VLOOKUP(B15,原材料价格表!$B$2:$G$436,3,0) | E15: =VLOOKUP(B15,原材料价格表!$B$2:$G$436,6,0) | F15: =VLOOKUP(B15,原材料价格表!$B$2:$G$436,5,0) | G15: 1 | H15: =E15/F15/G15 | I15: 1000 | J15: =H15*I15
B16: 果葡糖浆 | C16: =VLOOKUP(B16,原材料价格表!$B$2:$G$436,2,0) | D16: =VLOOKUP(B16,原材料价格表!$B$2:$G$436,3,0) | E16: =VLOOKUP(B16,原材料价格表!$B$2:$G$436,6,0) | F16: =VLOOKUP(B16,原材料价格表!$B$2:$G$436,5,0) | G16: 1 | H16: =E16/F16/G16 | I16: 35 | J16: =H16*I16
B17: 售价 | D17: 售卖份量/g | E17: =SUM(I14:I16)-2 | F17: 总成本（元） | G17: =SUM(J14:J16) | H17: 毛利/元 | I17: =C17-G17 | J17: 毛利率 | K17: =I17/C17
A18: 五指毛桃山茶 | B18: 五指毛桃茶汤 | C18: =VLOOKUP(B18,原材料价格表!$B$2:$G$436,2,0) | D18: =VLOOKUP(B18,原材料价格表!$B$2:$G$436,3,0) | E18: =VLOOKUP(B18,原材料价格表!$B$2:$G$436,6,0) | F18: =VLOOKUP(B18,原材料价格表!$B$2:$G$436,5,0) | G18: 1 | H18: =E18/F18/G18 | I18: 200 | J18: =H18*I18
B19: 薏仁罐头 | C19: =VLOOKUP(B19,原材料价格表!$B$2:$G$436,2,0) | D19: =VLOOKUP(B19,原材料价格表!$B$2:$G$436,3,0) | E19: =VLOOKUP(B19,原材料价格表!$B$2:$G$436,6,0) | F19: =VLOOKUP(B19,原材料价格表!$B$2:$G$436,5,0) | G19: 1 | H19: =E19/F19/G19 | I19: 40 | J19: =H19*I19
B20: 果葡糖浆 | C20: =VLOOKUP(B20,原材料价格表!$B$2:$G$436,2,0) | D20: =VLOOKUP(B20,原材料价格表!$B$2:$G$436,3,0) | E20: =VLOOKUP(B20,原材料价格表!$B$2:$G$436,6,0) | F20: =VLOOKUP(B20,原材料价格表!$B$2:$G$436,5,0) | G20: 1 | H20: =E20/F20/G20 | I20: 10 | J20: =H20*I20
B21: 冰块 | C21: =VLOOKUP(B21,原材料价格表!$B$2:$G$436,2,0) | D21: =VLOOKUP(B21,原材料价格表!$B$2:$G$436,3,0) | E21: =VLOOKUP(B21,原材料价格表!$B$2:$G$436,6,0) | F21: =VLOOKUP(B21,原材料价格表!$B$2:$G$436,5,0) | G21: 1 | H21: =E21/F21/G21 | I21: 250 | J21: =H21*I21
B22: 五指毛桃干 | C22: =VLOOKUP(B22,原材料价格表!$B$2:$G$436,2,0) | D22: =VLOOKUP(B22,原材料价格表!$B$2:$G$436,3,0) | E22: =VLOOKUP(B22,原材料价格表!$B$2:$G$436,6,0) | F22: =VLOOKUP(B22,原材料价格表!$B$2:$G$436,5,0) | G22: 1 | H22: =E22/F22/G22 | I22: 10 | J22: =H22*I22
B23: 售价 | C23: 18 | D23: 售卖份量/g | E23: =SUM(I18:I22) | F23: 总成本（元） | G23: =SUM(J18:J22) | H23: 毛利/元 | I23: =C23-G23 | J23: 毛利率 | K23: =I23/C23
A24: 鸭屎香乌龙茶汤（半成品） | B24: 鸭屎香乌龙茶茶叶 | C24: =VLOOKUP(B24,原材料价格表!$B$2:$G$436,2,0) | D24: =VLOOKUP(B24,原材料价格表!$B$2:$G$436,4,0) | E24: =VLOOKUP(B24,原材料价格表!$B$2:$G$436,6,0) | F24: =VLOOKUP(B24,原材料价格表!$B$2:$G$436,5,0) | G24: 1 | H24: =E24/F24/G24 | I24: 30 | J24: =H24*I24
B25: 水 | C25: =VLOOKUP(B25,原材料价格表!$B$2:$G$436,2,0) | D25: =VLOOKUP(B25,原材料价格表!$B$2:$G$436,4,0) | E25: =VLOOKUP(B25,原材料价格表!$B$2:$G$436,6,0) | F25: =VLOOKUP(B25,原材料价格表!$B$2:$G$436,5,0) | G25: 1 | H25: =E25/F25/G25 | I25: 1800 | J25: =H25*I25
B26: 售价 | D26: 售卖份量/g | E26: =SUM(I24:I25)-30 | F26: 总成本（元） | G26: =SUM(J24:J25) | H26: 毛利/元 | I26: =C26-G26 | J26: 毛利率 | K26: =I26/C26
A27: 柠檬山茶 | B27: 香水柠檬 | C27: =VLOOKUP(B27,原材料价格表!$B$2:$G$436,2,0) | D27: =VLOOKUP(B27,原材料价格表!$B$2:$G$436,4,0) | E27: =VLOOKUP(B27,原材料价格表!$B$2:$G$436,6,0) | F27: =VLOOKUP(B27,原材料价格表!$B$2:$G$436,5,0) | G27: 0.85 | H27: =E27/F27/G27 | I27: 30 | J27: =H27*I27
B28: 鸭屎香乌龙茶汤 | C28: =VLOOKUP(B28,原材料价格表!$B$2:$G$436,2,0) | D28: =VLOOKUP(B28,原材料价格表!$B$2:$G$436,4,0) | E28: =VLOOKUP(B28,原材料价格表!$B$2:$G$436,6,0) | F28: =VLOOKUP(B28,原材料价格表!$B$2:$G$436,5,0) | G28: 1 | H28: =E28/F28/G28 | I28: 200 | J28: =H28*I28
B29: 果葡糖浆 | C29: =VLOOKUP(B29,原材料价格表!$B$2:$G$436,2,0) | D29: =VLOOKUP(B29,原材料价格表!$B$2:$G$436,4,0) | E29: =VLOOKUP(B29,原材料价格表!$B$2:$G$436,6,0) | F29: =VLOOKUP(B29,原材料价格表!$B$2:$G$436,5,0) | G29: 1 | H29: =E29/F29/G29 | I29: 40 | J29: =H29*I29
B30: 香水柠檬 | C30: =VLOOKUP(B30,原材料价格表!$B$2:$G$436,2,0) | D30: =VLOOKUP(B30,原材料价格表!$B$2:$G$436,4,0) | E30: =VLOOKUP(B30,原材料价格表!$B$2:$G$436,6,0) | F30: =VLOOKUP(B30,原材料价格表!$B$2:$G$436,5,0) | G30: 0.85 | H30: =E30/F30/G30 | I30: 30 | J30: =H30*I30
B31: 黄柠檬 | C31: =VLOOKUP(B31,原材料价格表!$B$2:$G$436,2,0) | D31: =VLOOKUP(B31,原材料价格表!$B$2:$G$436,4,0) | E31: =VLOOKUP(B31,原材料价格表!$B$2:$G$436,6,0) | F31: =VLOOKUP(B31,原材料价格表!$B$2:$G$436,5,0) | G31: 0.85 | H31: =E31/F31/G31 | I31: 15 | J31: =H31*I31
B32: 售价 | C32: 18 | D32: 售卖份量/g | E32: =SUM(I27:I31) | F32: 总成本（元） | G32: =SUM(J27:J31) | H32: 毛利/元 | I32: =C32-G32 | J32: 毛利率 | K32: =I32/C32
A33: 雪域藏茶茶汤（半成品） | B33: 雪域藏茶 | C33: =VLOOKUP(B33,原材料价格表!$B$2:$G$436,2,0) | D33: =VLOOKUP(B33,原材料价格表!$B$2:$G$436,4,0) | E33: =VLOOKUP(B33,原材料价格表!$B$2:$G$436,6,0) | F33: =VLOOKUP(B33,原材料价格表!$B$2:$G$436,5,0) | G33: 1 | H33: =E33/F33/G33 | I33: 50 | J33: =H33*I33
B34: 水 | C34: =VLOOKUP(B34,原材料价格表!$B$2:$G$436,2,0) | D34: =VLOOKUP(B34,原材料价格表!$B$2:$G$436,4,0) | E34: =VLOOKUP(B34,原材料价格表!$B$2:$G$436,6,0) | F34: =VLOOKUP(B34,原材料价格表!$B$2:$G$436,5,0) | G34: 1 | H34: =E34/F34/G34 | I34: 1500 | J34: =H34*I34
B35: 售价 | D35: 售卖份量/g | E35: 1500 | F35: 总成本（元） | G35: =SUM(J33:J34) | H35: 毛利/元 | I35: =C35-G35 | J35: 毛利率 | K35: =I35/C35
A36: 柠檬藏茶 | B36: 香水柠檬 | C36: =VLOOKUP(B36,原材料价格表!$B$2:$G$436,2,0) | D36: =VLOOKUP(B36,原材料价格表!$B$2:$G$436,4,0) | E36: =VLOOKUP(B36,原材料价格表!$B$2:$G$436,6,0) | F36: =VLOOKUP(B36,原材料价格表!$B$2:$G$436,5,0) | G36: 0.85 | H36: =E36/F36/G36 | I36: 40 | J36: =H36*I36
B37: 蔗糖糖浆 | C37: =VLOOKUP(B37,原材料价格表!$B$2:$G$436,2,0) | D37: =VLOOKUP(B37,原材料价格表!$B$2:$G$436,4,0) | E37: =VLOOKUP(B37,原材料价格表!$B$2:$G$436,6,0) | F37: =VLOOKUP(B37,原材料价格表!$B$2:$G$436,5,0) | G37: 1 | H37: =E37/F37/G37 | I37: 45 | J37: =H37*I37
B38: 金桔柠檬果蓉 | C38: =VLOOKUP(B38,原材料价格表!$B$2:$G$436,2,0) | D38: =VLOOKUP(B38,原材料价格表!$B$2:$G$436,4,0) | E38: =VLOOKUP(B38,原材料价格表!$B$2:$G$436,6,0) | F38: =VLOOKUP(B38,原材料价格表!$B$2:$G$436,5,0) | G38: 1 | H38: =E38/F38/G38 | I38: 10 | J38: =H38*I38
B39: 冰块 | C39: =VLOOKUP(B39,原材料价格表!$B$2:$G$436,2,0) | D39: =VLOOKUP(B39,原材料价格表!$B$2:$G$436,4,0) | E39: =VLOOKUP(B39,原材料价格表!$B$2:$G$436,6,0) | F39: =VLOOKUP(B39,原材料价格表!$B$2:$G$436,5,0) | G39: 1 | H39: =E39/F39/G39 | I39: 500 | J39: =H39*I39
B40: 雪域藏茶茶汤 | C40: =VLOOKUP(B40,原材料价格表!$B$2:$G$436,2,0) | D40: =VLOOKUP(B40,原材料价格表!$B$2:$G$436,4,0) | E40: =VLOOKUP(B40,原材料价格表!$B$2:$G$436,6,0) | F40: =VLOOKUP(B40,原材料价格表!$B$2:$G$436,5,0) | G40: 1 | H40: =E40/F40/G40 | I40: 200 | J40: =H40*I40
...

Sheet 原材料价格表
A1: 分类 | B1: 原材料名称 | C1: 进货渠道 | D1: 品牌 | E1: 规格 | F1: 基础单位数量(g) | G1: 采购价格(元) | H1: 储存方式 | I1: 标准出成率 | J1: 基础单价(元/g) | K1: 备注 | L1: 分类 | M1: 是否供应链化 | N1: 付款方式
A2: 干杂 | B2: 红油 | C2: 自制 | F2: 500 | G2: 27 | H2: 常温 | I2: 0.95 | J2: 0.05 | L2: 干杂 | P2: 采购渠道：
A3: 干杂 | B3: 水 | C3: 自制 | F3: 500 | G3: 0 | I3: 1 | L3: 干杂 | P3: 1.成都牛肉供货商
B4: 冰块 | C4: 自制 | F4: 500 | G4: 0 | I4: 1 | P4: 2.绵阳蔬菜
A5: 自制酱料 | B5: 香茅酱 | C5: 自制 | F5: ='肉类、海鲜（涮菜）'!F116 | G5: ='肉类、海鲜（涮菜）'!H116 | I5: 1 | L5: 自制酱料 | P5: 3.绵阳干杂
A6: 自制酱料 | B6: 干巴菌酱 | C6: 自制 | F6: ='肉类、海鲜（涮菜）'!F140 | G6: ='肉类、海鲜（涮菜）'!H140 | I6: 1 | L6: 自制酱料 | P6: 4.绵阳海鲜
A7: 自制 | B7: 鸭屎香乌龙茶汤 | C7: 自制 | F7: =糖水铺!E26 | G7: =糖水铺!G26 | H7: 冷藏 | I7: 1 | L7: 自制 | P7: 5.酒商
A8: 自制 | B8: 山茶花茶汤 | C8: 自制 | F8: =糖水铺!E7 | G8: =糖水铺!G7 | H8: 冷藏 | I8: 1 | L8: 自制 | P8: 6.绵阳干冰
A9: 自制 | B9: 五指毛桃茶汤 | C9: 自制 | F9: =糖水铺!E17 | G9: =糖水铺!G17 | H9: 冷藏 | I9: 1 | L9: 自制 | P9: 7.虾滑群
A10: 海鲜 | B10: 虾滑 | C10: 7.虾滑群 | D10: 亚万食品 | E10: 150g*30包/件 | F10: 125 | G10: 9.17 | H10: 冷冻 | I10: 1 | J10: 0.092 | L10: 海鲜 | N10: 货到付款 | P10: 8.乌鱼片采购
A11: 海鲜 | B11: 乌鱼片 | C11: 8.乌鱼片采购 | D11: 四川双柒食品有限公司 | E11: 500g/袋 | F11: 500 | G11: 22 | H11: 冷冻 | I11: 0.95 | J11: 0.0454 | L11: 海鲜 | N11: 货到付款 | P11: 9.泓泰商贸（柠檬粉、味露、鱼露）
A12: 肉类 | B12: 雪花松板肉 | C12: 网采 | E12: 400g/袋 | F12: 400 | G12: 16 | H12: 冷冻 | I12: 1 | J12: 0.04 | L12: 肉类 | P12: 10.干茅草、五指毛桃群
A13: 肉类 | B13: 猪响皮 | C13: 网采 | D13: 土特产店铺 | E13: 称重 | F13: 500 | G13: 25 | H13: 常温 | I13: 0.95 | J13: 0.05 | L13: 肉类
A14: 肉类 | B14: 糯米午餐肉 | C14: 网采 | D14: 盛佳佳茂 | E14: 340g/罐 | F14: 340 | G14: 10.3 | H14: 常温 | I14: 1 | J14: 0.030294 | L14: 肉类
A15: 蔬菜 | B15: 干花菜 | C15: 网采 | D15: 醉川味四川花椒辣椒 | E15: 2500g/85.32元 | F15: 500 | G15: 17 | H15: 常温 | I15: 1 | J15: 0.034 | L15: 蔬菜
A16: 蔬菜 | B16: 干贡菜 | C16: 网采 | D16: 醉川味四川花椒辣椒 | E16: 称重 | F16: 500 | G16: 45.5 | H16: 常温 | I16: 1 | J16: 0.091 | L16: 蔬菜
A17: 蔬菜 | B17: 干黄花 | C17: 网采 | D17: 味江涞食品商行 | E17: 20斤/件/530元 | F17: 500 | G17: 26.5 | H17: 常温 | I17: 1 | J17: 0.053 | L17: 蔬菜
A18: 干杂 | B18: 野菜卷（成品） | C18: 网采 | D18: 惠厨食品供应商-国味缘 | E18: 170元/件 20袋/件 10根/袋 | F18: 1 | G18: =170/20/10 | H18: 冷藏 | I18: 1 | K18: 根 | L18: 干杂
A19: 干杂 | B19: 木姜子油 | C19: 网采 | E19: 780ml/瓶 | F19: 500 | G19: =41.5/780*500 | H19: 常温 | I19: 1 | L19: 干杂
A20: 干杂 | B20: 金蒜酥 | C20: 9.泓泰商贸 | E20: 500g/袋 | F20: 500 | G20: 20 | H20: 常温 | I20: 1 | J20: 0.04 | L20: 干杂
A21: 干杂 | B21: 黑松露酱 | C21: 网采 | D21: 若桑食品批发-欧萨 | E21: 500g/罐 | F21: 500 | G21: 125 | H21: 冷藏 | I21: 1 | J21: 0.25 | L21: 干杂
A22: 干杂 | B22: 墨鱼汁 | C22: 网采 | D22: 若桑食品批发-欧萨 | E22: 500g/罐 | F22: 500 | G22: 112 | H22: 冷藏 | I22: 1 | J22: 0.224 | L22: 干杂
A23: 干杂 | B23: 黄心皮蛋 | C23: 网采 | D23: 川农小温的小店 | E23: 个 | F23: 1 | G23: 1.6 | H23: 常温 | I23: 1 | J23: 1.6 | K23: 单位：个 | L23: 干杂
A24: 干杂 | B24: 春卷皮 | C24: 网采 | D24: 夜郎食味贵州特产店 | E24: 65张/斤/包 | F24: 1 | G24: 0.2 | H24: 冷藏 | I24: 1 | J24: 0.2 | K24: 单位：张 | L24: 干杂
A25: 干杂 | B25: 溏心蛋 | C25: 网采 | D25: 凡人乐旗舰店 | E25: 枚 | F25: 枚 | G25: 2 | H25: 常温 | I25: 1 | L25: 干杂
A26: 酱料 | B26: 豆腐乳 | C26: 网采 | D26: 百花串 | E26: 310g/瓶 | F26: 310 | G26: 7.17 | H26: 冷藏 | I26: 1 | J26: 0.023129 | L26: 酱料
A27: 酱料 | B27: 水豆豉 | C27: 网采 | D27: 贵山辣 | E27: 610g/瓶 | F27: 610 | G27: 7.13 | H27: 冷藏 | I27: 1 | J27: 0.011689 | L27: 酱料
A28: 干杂 | B28: 黄天鹅无菌蛋 | C28: 集采 | E28: 个 | F28: 1 | G28: 1.89 | H28: 常温15天 | I28: 1 | J28: 1.89 | K28: 单位：个 | L28: 干杂
A29: 干杂 | B29: 玫瑰乳扇 | C29: 网采 | D29: 极丝食品旗舰店 | E29: 500g/袋 | F29: 500 | G29: 34.2 | H29: 冷藏 | I29: 1 | J29: 0.0684 | L29: 干杂
A30: 酱料 | B30: 玫瑰酱 | C30: 网采 | D30: 觅滇食品专营店 | E30: 5000g/瓶 | F30: 5000 | G30: 64.5 | H30: 冷藏 | I30: 1 | J30: 0.0129 | L30: 酱料
A31: 酱料 | B31: 百香果原汁 | C31: 网采 | D31: 嘉优鲜果园 | E31: 10斤/80.8元 | F31: 500 | G31: 8.08 | H31: 冷藏 | I31: 1 | J31: 0.01616 | L31: 酱料
A32: 干杂 | B32: 干巴菌 | C32: 网采 | E32: 2斤/250元 | F32: 500 | G32: 130 | H32: 常温 | I32: 1 | J32: 0.26 | L32: 干杂
A33: 干杂 | B33: 干玫瑰花 | C33: 网采 | F33: 500 | G33: 75 | H33: 常温 | I33: 1 | J33: 0.236 | L33: 干杂
A34: 肉类 | B34: 宣威火腿 | C34: 网采 | E34: 500g/块 | F34: 500 | G34: 36.96 | H34: 冷藏 | I34: 0.9 | J34: 0.07392 | L34: 肉类
A35: 干杂 | B35: 帕玛森干酪 | C35: 网采 | E35: 200g/块 | F35: 200 | G35: 27.6 | I35: 1 | J35: 0.149 | L35: 干杂
A36: 干杂 | B36: 香草冰淇淋 | C36: 网采 | E36: 3.5kg/桶 | F36: =7*500 | G36: 120 | I36: 1 | L36: 干杂
A37: 干杂 | B37: 碧根果碎 | C37: 网采 | E37: 500g*2罐/60元 | F37: 500 | G37: 30 | I37: 1 | J37: 0.06 | L37: 干杂
A38: 干杂 | B38: 刺梨果干 | C38: 网采 | E38: 450g/罐 | F38: 450 | G38: 12.4 | H38: 常温 | I38: 1 | J38: 0.027556 | L38: 干杂
A39: 糖水铺 | B39: 刺梨原浆 | C39: 网采 | E39: 200ml/袋*10袋/件 | F39: 200 | G39: =47.41/10 | I39: 1 | L39: 糖水铺
A40: 蔬菜 | B40: 水蜜桃 | C40: 绵阳水果 | F40: 500 | G40: 25 | H40: 冷藏 | I40: 0.9 | J40: 0.05 | L40: 蔬菜 | N40: 先款后货
...
